Workbook

Sheet README
A1: DEALER TERRITORY & FEE MODEL — HOW TO READ THIS WORKBOOK
A2: Built 7 September 2026 on PBS Census 2023. Everything here is a formula chain — change an input and every sheet updates.
A4: THE IDEA IN ONE PARAGRAPH
A5: A pump is bought when a house is built, or when the old pump dies. So each territory's value is the number of houses in it, how fast new ones are being
A6: built, how many old pumps are due for replacement, and how much a customer there will pay. We turn each of those into a number, weight them, and get
A7: a 'Fee Unit' score for each territory. One anchor price (e.g. DHA Phase VIII = Rs 1.5 Cr) fixes what a Fee Unit is worth in rupees, and every other
A8: fee follows arithmetically. The same market numbers also set each dealer's sales quota, and from that we show what they can earn.
A10: COLOUR CODE
A11: Blue text on yellow = an input you can change. Black text = a formula. Green text = pulled from another sheet.
A12: Cream row under each header = plain-English explanation of that column.
A14: THE SHEETS, IN ORDER
A15: 1. Assumptions Every lever in one place. Change these; touch nothing else.
... A40: ASSUMED on the Assumptions sheet with a note on where the real number comes from. The census figures and the arithmetic are not assumptions.

Sheet Visuals
A1: VISUALS — LIVE CHARTS
A2: Every chart reads from the other sheets. Change an assumption or the active scenario and they redraw. Nothing on this sheet is typed in.
Q4: HOW TO USE THIS SHEET
Q5: 1. Go to Assumptions. Change any blue cell.
Q6: 2. Set 'Active scenario' to A or B.
Q7: 3. Come back here — every chart has redrawn.
Q9: Chart 1 compares the two anchors directly.
Q10: Charts 2-3 are top line and bottom line per territory.
Q11: Chart 4 is the sanity check: any bar above 48 months
Q12: is a territory that will not sell at that anchor.
Q13: Chart 5 is the quota. Charts 6-7 are the census projection.

Sheet Assumptions
A1: ASSUMPTIONS — EVERY LEVER IN THE MODEL
A2: Blue-on-yellow cells are yours to change. Column C says what each one does and whether it is measured or assumed. Nothing else in the workbook needs editing.
A4: HOW HOUSEHOLDS BECOME PUMP POINTS
A5: Pump sets per independent house | B5: 1.2 | C5: An independent house usually needs one pump and often two (transfer + booster). 1.2 is a blend. ASSUMED — replace from your installation records.
A6: Flats per booster set | B6: 40 | C6: One booster set serves a whole block of flats, so a flat is worth 1/40th of a house. ASSUMED — replace from your records.
A7: Average pump life (years) | B7: 9 | C7: How long a pump lasts before it is replaced. Drives the replacement channel. ASSUMED.
A8: Dealership term (years) | B8: 4 | C8: The window over which new-build and replacement demand is counted, and over which the fee is amortised.
A9: Growth rate cap | B9: 0.035 | C9: Census growth 2017-23 is capped here. Karachi's raw 4.09% mostly reflects a disputed 2017 undercount, not real growth.
A11: COMMERCIALS
A12: Average pump selling price (PKR) | B12: 125000 | C12: Supplied by you. Used for revenue and for converting the inventory credit into units.
A13: Dealer gross margin | B13: 0.22 | C13: The share of each sale the dealer keeps before their own costs. ASSUMED — drives every profit and payback figure.
A14: Inventory credit (fraction of fee) | B14: 0.5 | C14: The dealer is credited stock worth this share of their fee. Their real cash outlay is the remainder.
A15: Whole-city exclusivity premium | B15: 1.1 | C15: Added when one dealer takes an entire city, to price the option of blocking future entrants.
A17: HOW MUCH A CUSTOMER PAYS — ASP TIER MULTIPLIERS
A18: ASP S — Hyper (DHA Ph VIII class) | B18: 8 | C18: Newest premium bungalow stock at the highest achievable price. ASSUMED.
A19: ASP A — Premium | B19: 3 | C19: Established premium: Clifton, DHA I-VI, Lahore Cantt, CDA sectors. ASSUMED.
A20: ASP B — Upper-mid | B20: 1.6 | C20: ASSUMED.
A21: ASP C — Mass | B21: 1 | C21: Baseline. Everything else is a multiple of this.
A23: HOW MUCH OF THE MARKET GRUNDFOS CAN WIN — SHARE BY TIER
A24: Share S — Hyper | B24: 0.06 | C24: Share of ALL pump installations in that territory, not just the premium ones. ASSUMED — the biggest single driver of quota.
A25: Share A — Premium | B25: 0.04 | C25: ASSUMED.
A26: Share B — Upper-mid | B26: 0.015 | C26: ASSUMED.
A27: Share C — Mass | B27: 0.003 | C27: Grundfos loses to cheap local pumps here. ASSUMED.
A29: HOW THE FEE INDEX IS WEIGHTED (must total 100%)
A30: Weight: new construction | B30: 0.45 | C30: Houses being built now — a decision being made today.
A31: Weight: replacement due | B31: 0.35 | C31: Old pumps reaching end of life inside the term.
A32: Weight: installed base | B32: 0.15 | C32: Everything standing — service, spares, second units.
A33: Weight: area | B33: 0.05 | C33: Territorial exclusivity. Kept small so a dealer is not charged for empty land.
A34: Weight total | B34: =$B$30+$B$31+$B$32+$B$33 -> 1 | C34: Must read 100%.
A36: PRICE ANCHORS — A IS THE CHOSEN ANCHOR
A37: Scenario A: anchor on | B37: Islamabad | C37: CHOSEN ANCHOR. Whole city of Islamabad. A territory name from PumpPoints column B, or a city name.
A38: Scenario A: anchor fee (PKR) | B38: 10000000 | C38: Islamabad whole-city rights = Rs 1.00 Cr. Every other fee in the model follows from this.
A39: Scenario B: anchor on | B39: DHA Phase VIII + Sahil | C39: Alternative, kept for comparison only.
A40: Scenario B: anchor fee (PKR) | B40: 15000000 | C40: The higher-anchor alternative. Not in use.
A41: Active scenario for Economics & Visuals | B41: A | C41: A = Islamabad Rs 1 Cr (chosen). B = DHA Rs 1.5 Cr.
A42: Scenario A rate (PKR per Fee Unit) | B42: =B38/IFERROR(INDEX(FeeSchedule!$F$6:$F$34,MATCH(B37,FeeSchedule!$B$6:$B$34,0)),SUMIFS(FeeSchedule!$F$6:$F$34,FeeSchedule!$A$6:$A$34,B37)*$B$15) -> 1058239.3 | C42: Computed.
A43: Scenario B rate (PKR per Fee Unit) | B43: =B40/IFERROR(INDEX(FeeSchedule!$F$6:$F$34,MATCH(B39,FeeSchedule!$B$6:$B$34,0)),SUMIFS(FeeSchedule!$F$6:$F$34,FeeSchedule!$A$6:$A$34,B39)*$B$15) -> 12350370 | C43: Computed.
A44: Active rate (PKR per Fee Unit) | B44: =IF($B$41="B",$B$43,$B$42) -> 1058239.3 | C44: Computed.
A46: YEAR-ONE QUOTA RAMP
A47: Ramp Q1 | B47: 0.5 | C47: A new dealer cannot hit full speed while still hiring technicians.
...

Sheet CensusBase
A1: CENSUS BASE — THE 22 OFFICIAL REGIONS
A2: Columns C-H are PBS Census 2023 figures plus one stated assumption (house share). Everything from column I onward is arithmetic on those. The cream row explains each column.
A4: City | B4: Region | C4: Area km² | D4: Pop 2017 | E4: Pop 2023 | F4: HH size | G4: House share | H4: ASP tier | I4: Raw growth | J4: Capped growth | K4: SPP factor | L4: HH 2026 | M4: SPP 2018 | N4: SPP 2026 | O4: SPP 2030
B5: Census unit | C5: Census, sq km | D5: Census 2017 | E5: Census 2023 | F5: People per household, census | G5: Share of households that are independent houses (not flats). ASSUMED. | H5: Price tier: S/A/B/C, see Assumptions | I5: (Pop2023 / Pop2017)^(1/6) - 1: yearly growth between the two censuses | J5: Raw growth, but no lower than 0% and no higher than the cap | K5: Pump points per household = share × sets-per-house + (1-share) / flats-per-set | L5: Households in 2026 = Pop2023 grown 3 years, divided by HH size | M5: Pump points 8 years before the term — what is now due for replacement | N5: Pump points today | O5: Pump points at the end of the term
A6: Karachi | B6: Karachi East | C6: 139 | D6: 2875315 | E6: 3921742 | F6: 5.9 | G6: 0.35 | H6: B | I6: =(E6/D6)^(1/6)-1 -> 0.053090265 | J6: =MAX(0,MIN(Assumptions!$B$9,I6)) -> 0.035 | K6: =G6*Assumptions!$B$5+(1-G6)/Assumptions!$B$6 -> 0.43625 | L6: =E6*(1+J6)^3/F6 -> 736967.03 | M6: =E6*(1+J6)^-5/F6*K6 -> 244152.23 | N6: =L6*K6 -> 321501.87 | O6: =E6*(1+J6)^7/F6*K6 -> 368930.79
A7: Karachi | B7: Karachi Central | C7: 69 | D7: 2971382 | E7: 3822325 | F7: 5.8 | G7: 0.45 | H7: C | I7: =(E7/D7)^(1/6)-1 -> 0.042865228 | J7: =MAX(0,MIN(Assumptions!$B$9,I7)) -> 0.035 | K7: =G7*Assumptions!$B$5+(1-G7)/Assumptions!$B$6 -> 0.55375 | L7: =E7*(1+J7)^3/F7 -> 730668.97 | M7: =E7*(1+J7)^-5/F7*K7 -> 307263.95 | N7: =L7*K7 -> 404607.94 | O7: =E7*(1+J7)^7/F7*K7 -> 464296.92
A8: Karachi | B8: Korangi | C8: 108 | D8: 2577556 | E8: 3128971 | F8: 6.3 | G8: 0.6 | H8: C | I8: =(E8/D8)^(1/6)-1 -> 0.032838071 | J8: =MAX(0,MIN(Assumptions!$B$9,I8)) -> 0.032838071 | K8: =G8*Assumptions!$B$5+(1-G8)/Assumptions!$B$6 -> 0.73 | L8: =E8*(1+J8)^3/F8 -> 547214.63 | M8: =E8*(1+J8)^-5/F8*K8 -> 308476.91 | N8: =L8*K8 -> 399466.68 | O8: =E8*(1+J8)^7/F8*K8 -> 454579.15
A9: Karachi | B9: Karachi West | C9: 370 | D9: 2077228 | E9: 2679380 | F9: 5.7 | G9: 0.7 | H9: C | I9: =(E9/D9)^(1/6)-1 -> 0.043337996 | J9: =MAX(0,MIN(Assumptions!$B$9,I9)) -> 0.035 | K9: =G9*Assumptions!$B$5+(1-G9)/Assumptions!$B$6 -> 0.8475 | L9: =E9*(1+J9)^3/F9 -> 521171.32 | M9: =E9*(1+J9)^-5/F9*K9 -> 335426.53 | N9: =L9*K9 -> 441692.69 | O9: =E9*(1+J9)^7/F9*K9 -> 506852.52
A10: Karachi | B10: Malir | C10: 2160 | D10: 1924346 | E10: 2432248 | F10: 5.7 | G10: 0.75 | H10: B | I10: =(E10/D10)^(1/6)-1 -> 0.039810301 | J10: =MAX(0,MIN(Assumptions!$B$9,I10)) -> 0.035 | K10: =G10*Assumptions!$B$5+(1-G10)/Assumptions!$B$6 -> 0.90625 | L10: =E10*(1+J10)^3/F10 -> 473101.2 | M10: =E10*(1+J10)^-5/F10*K10 -> 325596.16 | N10: =L10*K10 -> 428747.96 | O10: =E10*(1+J10)^7/F10*K10 -> 491998.15
A11: Karachi | B11: Karachi South | C11: 122 | D11: 1769230 | E11: 2329764 | F11: 5.4 | G11: 0.55 | H11: A | I11: =(E11/D11)^(1/6)-1 -> 0.046938745 | J11: =MAX(0,MIN(Assumptions!$B$9,I11)) -> 0.035 | K11: =G11*Assumptions!$B$5+(1-G11)/Assumptions!$B$6 -> 0.67125 | L11: =E11*(1+J11)^3/F11 -> 478342.78 | M11: =E11*(1+J11)^-5/F11*K11 -> 243837.63 | N11: =L11*K11 -> 321087.59 | O11: =E11*(1+J11)^7/F11*K11 -> 368455.39
A12: Karachi | B12: Keamari | C12: 559 | D12: 1829837 | E12: 2068451 | F12: 6.4 | G12: 0.7 | H12: C | I12: =(E12/D12)^(1/6)-1 -> 0.020638952 | J12: =MAX(0,MIN(Assumptions!$B$9,I12)) -> 0.020638952 | K12: =G12*Assumptions!$B$5+(1-G12)/Assumptions!$B$6 -> 0.8475 | L12: =E12*(1+J12)^3/F12 -> 343622.57 | M12: =E12*(1+J12)^-5/F12*K12 -> 247311.48 | N12: =L12*K12 -> 291220.13 | O12: =E12*(1+J12)^7/F12*K12 -> 316016.63
A13: Lahore | B13: Lahore City | C13: 214 | D13: 3644787 | E13: 4123354 | F13: 6.5 | G13: 0.75 | H13: C | I13: =(E13/D13)^(1/6)-1 -> 0.020774341 | J13: =MAX(0,MIN(Assumptions!$B$9,I13)) -> 0.020774341 | K13: =G13*Assumptions!$B$5+(1-G13)/Assumptions!$B$6 -> 0.90625 | L13: =E13*(1+J13)^3/F13 -> 674724.53 | M13: =E13*(1+J13)^-5/F13*K13 -> 518724.26 | N13: =L13*K13 -> 611469.1 | O13: =E13*(1+J13)^7/F13*K13 -> 663885.98
A14: Lahore | B14: Model Town | C14: 353 | D14: 2712398 | E14: 3244906 | F14: 6.5 | G14: 0.7 | H14: B | I14: =(E14/D14)^(1/6)-1 -> 0.030326296 | J14: =MAX(0,MIN(Assumptions!$B$9,I14)) -> 0.030326296 | K14: =G14*Assumptions!$B$5+(1-G14)/Assumptions!$B$6 -> 0.8475 | L14: =E14*(1+J14)^3/F14 -> 546025.74 | M14: =E14*(1+J14)^-5/F14*K14 -> 364380.02 | N14: =L14*K14 -> 462756.81 | O14: =E14*(1+J14)^7/F14*K14 -> 521497.17
A15: Lahore | B15: Shalimar | C15: 272 | D15: 2281557 | E15: 2670140 | F15: 6.3 | G15: 0.75 | H15: C | I15: =(E15/D15)^(1/6)-1 -> 0.026558693 | J15: =MAX(0,MIN(Assumptions!$B$9,I15)) -> 0.026558693 | K15: =G15*Assumptions!$B$5+(1-G15)/Assumptions!$B$6 -> 0.90625 | L15: =E15*(1+J15)^3/F15 -> 458505.8 | M15: =E15*(1+J15)^-5/F15*K15 -> 336916.73 | N15: =L15*K15 -> 415520.89 | O15: =E15*(1+J15)^7/F15*K15 -> 461453.56
A16: Lahore | B16: Lahore Cantt | C16: 466 | D16: 1632702 | E16: 1885098 | F16: 6.3 | G16: 0.85 | H16: A | I16: =(E16/D16)^(1/6)-1 -> 0.02424653 | J16: =MAX(0,MIN(Assumptions!$B$9,I16)) -> 0.02424653 | K16: =G16*Assumptions!$B$5+(1-G16)/Assumptions!$B$6 -> 1.02375 | L16: =E16*(1+J16)^3/F16 -> 321519.18 | M16: =E16*(1+J16)^-5/F16*K16 -> 271747.02 | N16: =L16*K16 -> 329155.26 | O16: =E16*(1+J16)^7/F16*K16 -> 362258.69
A17: Lahore | B17: Raiwind | C17: 467 | D17: 848541 | E17: 1080637 | F17: 6.3 | G17: 0.85 | H17: B | I17: =(E17/D17)^(1/6)-1 -> 0.041120905 | J17: =MAX(0,MIN(Assumptions!$B$9,I17)) -> 0.035 | K17: =G17*Assumptions!$B$5+(1-G17)/Assumptions!$B$6 -> 1.02375 | L17: =E17*(1+J17)^3/F17 -> 190178.03 | M17: =E17*(1+J17)^-5/F17*K17 -> 147853.45 | N17: =L17*K17 -> 194694.75 | O17: =E17*(1+J17)^7/F17*K17 -> 223416.71
... A27: Islamabad | B27: ICT Urban | C27: 206 | D27: 1014825 | E27: 1108872 | F27: 5.7 | G27: 0.6 | H27: A | I27: =(E27/D27)^(1/6)-1 -> 0.014880816 | J27: =MAX(0,MIN(Assumptions!$B$9,I27)) -> 0.014880816 | K27: =G27*Assumptions!$B$5+(1-G27)/Assumptions!$B$6 -> 0.73 | L27: =E27*(1+J27)^3/F27 -> 203353.52 | M27: =E27*(1+J27)^-5/F27*K27 -> 131902.86 | N27: =L27*K27 -> 148448.07 | O27: =E27*(1+J27)^7/F27*K27 -> 157483.38
B28: TOTAL — 22 regions | C28: =SUM(C6:C27) -> 11443 | D28: =SUM(D6:D27) -> 38229576 | E28: =SUM(E6:E27) -> 45871946 | L28: =SUM(L6:L27) -> 8143804 | M28: =SUM(M6:M27) -> 5403067.8 | N28: =SUM(N6:N27) -> 6692331.3 | O28: =SUM(O6:O27) -> 7460577.8
A30: SOURCES
A31: Population, area, household size: PBS Census 2023 Table 1 (Sindh, Punjab, KP, ICT district tables). Multan household total confirmed against PBS Table 34 to within 0.007%.
A32: House share is NOT in the census. PBS Table 20 gives Pakka/Semi-Pakka/Kacha (building material), not house vs flat. This column is a judgement to be replaced by
A33: building-approval records (SBCA/LDA/CDA/PDA/MDA) or by utility connection counts, which separate individual house meters from bulk building meters.

Sheet Projection
A1: PROJECTION — POPULATION AND HOUSEHOLDS, 2023 TO 2030
A2: Each region grows every year at its capped census rate. 2023 is the census; 2024-2030 are projections. The lower block adds the regions up by city; the Visuals sheet charts it.
A4: City | B4: Region | C4: Pop 2023 | D4: Pop 2024 | E4: Pop 2025 | F4: Pop 2026 | G4: Pop 2027 | H4: Pop 2028 | I4: Pop 2029 | J4: Pop 2030 | K4: HH 2023 | L4: HH 2024 | M4: HH 2025 | N4: HH 2026 | O4: HH 2027 | P4: HH 2028 | Q4: HH 2029 | R4: HH 2030
C5: Census | D5: Previous year × (1 + capped growth) | E5: Previous year × (1 + capped growth) | F5: Previous year × (1 + capped growth) | G5: Previous year × (1 + capped growth) | H5: Previous year × (1 + capped growth) | I5: Previous year × (1 + capped growth) | J5: Previous year × (1 + capped growth) | K5: Pop ÷ HH size | L5: Pop ÷ HH size | M5: Pop ÷ HH size | N5: Pop ÷ HH size | O5: Pop ÷ HH size | P5: Pop ÷ HH size | Q5: Pop ÷ HH size | R5: Pop ÷ HH size
A6: =CensusBase!A6 -> Karachi | B6: =CensusBase!B6 -> Karachi East | C6: =CensusBase!E6 -> 3921742 | D6: =C6*(1+CensusBase!$J6) -> 4059003 | E6: =D6*(1+CensusBase!$J6) -> 4201068.1 | F6: =E6*(1+CensusBase!$J6) -> 4348105.5 | G6: =F6*(1+CensusBase!$J6) -> 4500289.1 | H6: =G6*(1+CensusBase!$J6) -> 4657799.3 | I6: =H6*(1+CensusBase!$J6) -> 4820822.2 | J6: =I6*(1+CensusBase!$J6) -> 4989551 | K6: =C6/CensusBase!$F6 -> 664702.03 | L6: =D6/CensusBase!$F6 -> 687966.61 | M6: =E6/CensusBase!$F6 -> 712045.44 | N6: =F6/CensusBase!$F6 -> 736967.03 | O6: =G6/CensusBase!$F6 -> 762760.87 | P6: =H6/CensusBase!$F6 -> 789457.5 | Q6: =I6/CensusBase!$F6 -> 817088.52 | R6: =J6/CensusBase!$F6 -> 845686.61
A7: =CensusBase!A7 -> Karachi | B7: =CensusBase!B7 -> Karachi Central | C7: =CensusBase!E7 -> 3822325 | D7: =C7*(1+CensusBase!$J7) -> 3956106.4 | E7: =D7*(1+CensusBase!$J7) -> 4094570.1 | F7: =E7*(1+CensusBase!$J7) -> 4237880.1 | G7: =F7*(1+CensusBase!$J7) -> 4386205.9 | H7: =G7*(1+CensusBase!$J7) -> 4539723.1 | I7: =H7*(1+CensusBase!$J7) -> 4698613.4 | J7: =I7*(1+CensusBase!$J7) -> 4863064.8 | K7: =C7/CensusBase!$F7 -> 659021.55 | L7: =D7/CensusBase!$F7 -> 682087.31 | M7: =E7/CensusBase!$F7 -> 705960.36 | N7: =F7/CensusBase!$F7 -> 730668.97 | O7: =G7/CensusBase!$F7 -> 756242.39 | P7: =H7/CensusBase!$F7 -> 782710.87 | Q7: =I7/CensusBase!$F7 -> 810105.75 | R7: =J7/CensusBase!$F7 -> 838459.45
A8: =CensusBase!A8 -> Karachi | B8: =CensusBase!B8 -> Korangi | C8: =CensusBase!E8 -> 3128971 | D8: =C8*(1+CensusBase!$J8) -> 3231720.4 | E8: =D8*(1+CensusBase!$J8) -> 3337843.8 | F8: =E8*(1+CensusBase!$J8) -> 3447452.2 | G8: =F8*(1+CensusBase!$J8) -> 3560659.9 | H8: =G8*(1+CensusBase!$J8) -> 3677585.1 | I8: =H8*(1+CensusBase!$J8) -> 3798349.9 | J8: =I8*(1+CensusBase!$J8) -> 3923080.4 | K8: =C8/CensusBase!$F8 -> 496662.06 | L8: =D8/CensusBase!$F8 -> 512971.49 | M8: =E8/CensusBase!$F8 -> 529816.48 | N8: =F8/CensusBase!$F8 -> 547214.63 | O8: =G8/CensusBase!$F8 -> 565184.11 | P8: =H8/CensusBase!$F8 -> 583743.66 | Q8: =I8/CensusBase!$F8 -> 602912.68 | R8: =J8/CensusBase!$F8 -> 622711.17
A9: =CensusBase!A9 -> Karachi | B9: =CensusBase!B9 -> Karachi West | C9: =CensusBase!E9 -> 2679380 | D9: =C9*(1+CensusBase!$J9) -> 2773158.3 | E9: =D9*(1+CensusBase!$J9) -> 2870218.8 | F9: =E9*(1+CensusBase!$J9) -> 2970676.5 | G9: =F9*(1+CensusBase!$J9) -> 3074650.2 | H9: =G9*(1+CensusBase!$J9) -> 3182262.9 | I9: =H9*(1+CensusBase!$J9) -> 3293642.1 | J9: =I9*(1+CensusBase!$J9) -> 3408919.6 | K9: =C9/CensusBase!$F9 -> 470066.67 | L9: =D9/CensusBase!$F9 -> 486519 | M9: =E9/CensusBase!$F9 -> 503547.16 | N9: =F9/CensusBase!$F9 -> 521171.32 | O9: =G9/CensusBase!$F9 -> 539412.31 | P9: =H9/CensusBase!$F9 -> 558291.74 | Q9: =I9/CensusBase!$F9 -> 577831.95 | R9: =J9/CensusBase!$F9 -> 598056.07
A10: =CensusBase!A10 -> Karachi | B10: =CensusBase!B10 -> Malir | C10: =CensusBase!E10 -> 2432248 | D10: =C10*(1+CensusBase!$J10) -> 2517376.7 | E10: =D10*(1+CensusBase!$J10) -> 2605484.9 | F10: =E10*(1+CensusBase!$J10) -> 2696676.8 | G10: =F10*(1+CensusBase!$J10) -> 2791060.5 | H10: =G10*(1+CensusBase!$J10) -> 2888747.6 | I10: =H10*(1+CensusBase!$J10) -> 2989853.8 | J10: =I10*(1+CensusBase!$J10) -> 3094498.7 | K10: =C10/CensusBase!$F10 -> 426710.18 | L10: =D10/CensusBase!$F10 -> 441645.03 | M10: =E10/CensusBase!$F10 -> 457102.61 | N10: =F10/CensusBase!$F10 -> 473101.2 | O10: =G10/CensusBase!$F10 -> 489659.74 | P10: =H10/CensusBase!$F10 -> 506797.83 | Q10: =I10/CensusBase!$F10 -> 524535.76 | R10: =J10/CensusBase!$F10 -> 542894.51
A11: =CensusBase!A11 -> Karachi | B11: =CensusBase!B11 -> Karachi South | C11: =CensusBase!E11 -> 2329764 | D11: =C11*(1+CensusBase!$J11) -> 2411305.7 | E11: =D11*(1+CensusBase!$J11) -> 2495701.4 | F11: =E11*(1+CensusBase!$J11) -> 2583051 | G11: =F11*(1+CensusBase!$J11) -> 2673457.8 | H11: =G11*(1+CensusBase!$J11) -> 2767028.8 | I11: =H11*(1+CensusBase!$J11) -> 2863874.8 | J11: =I11*(1+CensusBase!$J11) -> 2964110.4 | K11: =C11/CensusBase!$F11 -> 431437.78 | L11: =D11/CensusBase!$F11 -> 446538.1 | M11: =E11/CensusBase!$F11 -> 462166.93 | N11: =F11/CensusBase!$F11 -> 478342.78 | O11: =G11/CensusBase!$F11 -> 495084.77 | P11: =H11/CensusBase!$F11 -> 512412.74 | Q11: =I11/CensusBase!$F11 -> 530347.19 | R11: =J11/CensusBase!$F11 -> 548909.34
A12: =CensusBase!A12 -> Karachi | B12: =CensusBase!B12 -> Keamari | C12: =CensusBase!E12 -> 2068451 | D12: =C12*(1+CensusBase!$J12) -> 2111141.7 | E12: =D12*(1+CensusBase!$J12) -> 2154713.4 | F12: =E12*(1+CensusBase!$J12) -> 2199184.4 | G12: =F12*(1+CensusBase!$J12) -> 2244573.3 | H12: =G12*(1+CensusBase!$J12) -> 2290898.9 | I12: =H12*(1+CensusBase!$J12) -> 2338180.7 | J12: =I12*(1+CensusBase!$J12) -> 2386438.3 | K12: =C12/CensusBase!$F12 -> 323195.47 | L12: =D12/CensusBase!$F12 -> 329865.88 | M12: =E12/CensusBase!$F12 -> 336673.97 | N12: =F12/CensusBase!$F12 -> 343622.57 | O12: =G12/CensusBase!$F12 -> 350714.58 | P12: =H12/CensusBase!$F12 -> 357952.96 | Q12: =I12/CensusBase!$F12 -> 365340.73 | R12: =J12/CensusBase!$F12 -> 372880.98
A13: =CensusBase!A13 -> Lahore | B13: =CensusBase!B13 -> Lahore City | C13: =CensusBase!E13 -> 4123354 | D13: =C13*(1+CensusBase!$J13) -> 4209014 | E13: =D13*(1+CensusBase!$J13) -> 4296453.5 | F13: =E13*(1+CensusBase!$J13) -> 4385709.4 | G13: =F13*(1+CensusBase!$J13) -> 4476819.7 | H13: =G13*(1+CensusBase!$J13) -> 4569822.6 | I13: =H13*(1+CensusBase!$J13) -> 4664757.7 | J13: =I13*(1+CensusBase!$J13) -> 4761665 | K13: =C13/CensusBase!$F13 -> 634362.15 | L13: =D13/CensusBase!$F13 -> 647540.61 | M13: =E13/CensusBase!$F13 -> 660992.84 | N13: =F13/CensusBase!$F13 -> 674724.53 | O13: =G13/CensusBase!$F13 -> 688741.49 | P13: =H13/CensusBase!$F13 -> 703049.64 | Q13: =I13/CensusBase!$F13 -> 717655.03 | R13: =J13/CensusBase!$F13 -> 732563.84
A14: =CensusBase!A14 -> Lahore | B14: =CensusBase!B14 -> Model Town | C14: =CensusBase!E14 -> 3244906 | D14: =C14*(1+CensusBase!$J14) -> 3343312 | E14: =D14*(1+CensusBase!$J14) -> 3444702.3 | F14: =E14*(1+CensusBase!$J14) -> 3549167.3 | G14: =F14*(1+CensusBase!$J14) -> 3656800.4 | H14: =G14*(1+CensusBase!$J14) -> 3767697.6 | I14: =H14*(1+CensusBase!$J14) -> 3881957.9 | J14: =I14*(1+CensusBase!$J14) -> 3999683.3 | K14: =C14/CensusBase!$F14 -> 499216.31 | L14: =D14/CensusBase!$F14 -> 514355.69 | M14: =E14/CensusBase!$F14 -> 529954.19 | N14: =F14/CensusBase!$F14 -> 546025.74 | O14: =G14/CensusBase!$F14 -> 562584.68 | P14: =H14/CensusBase!$F14 -> 579645.79 | Q14: =I14/CensusBase!$F14 -> 597224.3 | R14: =J14/CensusBase!$F14 -> 615335.9
A15: =CensusBase!A15 -> Lahore | B15: =CensusBase!B15 -> Shalimar | C15: =CensusBase!E15 -> 2670140 | D15: =C15*(1+CensusBase!$J15) -> 2741055.4 | E15: =D15*(1+CensusBase!$J15) -> 2813854.3 | F15: =E15*(1+CensusBase!$J15) -> 2888586.6 | G15: =F15*(1+CensusBase!$J15) -> 2965303.7 | H15: =G15*(1+CensusBase!$J15) -> 3044058.2 | I15: =H15*(1+CensusBase!$J15) -> 3124904.4 | J15: =I15*(1+CensusBase!$J15) -> 3207897.8 | K15: =C15/CensusBase!$F15 -> 423831.75 | L15: =D15/CensusBase!$F15 -> 435088.16 | M15: =E15/CensusBase!$F15 -> 446643.54 | N15: =F15/CensusBase!$F15 -> 458505.8 | O15: =G15/CensusBase!$F15 -> 470683.12 | P15: =H15/CensusBase!$F15 -> 483183.85 | Q15: =I15/CensusBase!$F15 -> 496016.58 | R15: =J15/CensusBase!$F15 -> 509190.13
A16: =CensusBase!A16 -> Lahore | B16: =CensusBase!B16 -> Lahore Cantt | C16: =CensusBase!E16 -> 1885098 | D16: =C16*(1+CensusBase!$J16) -> 1930805.1 | E16: =D16*(1+CensusBase!$J16) -> 1977620.4 | F16: =E16*(1+CensusBase!$J16) -> 2025570.8 | G16: =F16*(1+CensusBase!$J16) -> 2074683.9 | H16: =G16*(1+CensusBase!$J16) -> 2124987.8 | I16: =H16*(1+CensusBase!$J16) -> 2176511.4 | J16: =I16*(1+CensusBase!$J16) -> 2229284.2 | K16: =C16/CensusBase!$F16 -> 299221.9 | L16: =D16/CensusBase!$F16 -> 306477 | M16: =E16/CensusBase!$F16 -> 313908 | N16: =F16/CensusBase!$F16 -> 321519.18 | O16: =G16/CensusBase!$F16 -> 329314.91 | P16: =H16/CensusBase!$F16 -> 337299.65 | Q16: =I16/CensusBase!$F16 -> 345478 | R16: =J16/CensusBase!$F16 -> 353854.64
A17: =CensusBase!A17 -> Lahore | B17: =CensusBase!B17 -> Raiwind | C17: =CensusBase!E17 -> 1080637 | D17: =C17*(1+CensusBase!$J17) -> 1118459.3 | E17: =D17*(1+CensusBase!$J17) -> 1157605.4 | F17: =E17*(1+CensusBase!$J17) -> 1198121.6 | G17: =F17*(1+CensusBase!$J17) -> 1240055.8 | H17: =G17*(1+CensusBase!$J17) -> 1283457.8 | I17: =H17*(1+CensusBase!$J17) -> 1328378.8 | J17: =I17*(1+CensusBase!$J17) -> 1374872 | K17: =C17/CensusBase!$F17 -> 171529.68 | L17: =D17/CensusBase!$F17 -> 177533.22 | M17: =E17/CensusBase!$F17 -> 183746.88 | N17: =F17/CensusBase!$F17 -> 190178.03 | O17: =G17/CensusBase!$F17 -> 196834.26 | P17: =H17/CensusBase!$F17 -> 203723.45 | Q17: =I17/CensusBase!$F17 -> 210853.78 | R17: =J17/CensusBase!$F17 -> 218233.66
... A27: =CensusBase!A27 -> Islamabad | B27: =CensusBase!B27 -> ICT Urban | C27: =CensusBase!E27 -> 1108872 | D27: =C27*(1+CensusBase!$J27) -> 1125372.9 | E27: =D27*(1+CensusBase!$J27) -> 1142119.4 | F27: =E27*(1+CensusBase!$J27) -> 1159115.1 | G27: =F27*(1+CensusBase!$J27) -> 1176363.6 | H27: =G27*(1+CensusBase!$J27) -> 1193868.9 | I27: =H27*(1+CensusBase!$J27) -> 1211634.6 | J27: =I27*(1+CensusBase!$J27) -> 1229664.7 | K27: =C27/CensusBase!$F27 -> 194538.95 | L27: =D27/CensusBase!$F27 -> 197433.85 | M27: =E27/CensusBase!$F27 -> 200371.82 | N27: =F27/CensusBase!$F27 -> 203353.52 | O27: =G27/CensusBase!$F27 -> 206379.59 | P27: =H27/CensusBase!$F27 -> 209450.68 | Q27: =I27/CensusBase!$F27 -> 212567.48 | R27: =J27/CensusBase!$F27 -> 215730.66
B28: TOTAL — 22 regions | C28: =SUM(C6:C27) -> 45871946 | D28: =SUM(D6:D27) -> 47139522 | E28: =SUM(E6:E27) -> 48445677 | F28: =SUM(F6:F27) -> 49791630 | G28: =SUM(G6:G27) -> 51178639 | H28: =SUM(H6:H27) -> 52608003 | I28: =SUM(I6:I27) -> 54081065 | J28: =SUM(J6:J27) -> 55599209 | ... R28: =SUM(R6:R27) -> 9104366.3
A30: BY CITY
A31: City | B31: Pop 2023 | C31: Pop 2024 | D31: Pop 2025 | E31: Pop 2026 | F31: Pop 2027 | G31: Pop 2028 | H31: Pop 2029 | I31: Pop 2030 | J31: HH 2023 | K31: HH 2024 | L31: HH 2025 | M31: HH 2026 | N31: HH 2027 | O31: HH 2028 | P31: HH 2029 | Q31: HH 2030
A32: Karachi | B32: =SUMIFS(C$6:C$27,$A$6:$A$27,$A32) -> 20382881 | C32: =SUMIFS(D$6:D$27,$A$6:$A$27,$A32) -> 21059812 | D32: =SUMIFS(E$6:E$27,$A$6:$A$27,$A32) -> 21759601 | E32: =SUMIFS(F$6:F$27,$A$6:$A$27,$A32) -> 22483026 | F32: =SUMIFS(G$6:G$27,$A$6:$A$27,$A32) -> 23230897 | G32: =SUMIFS(H$6:H$27,$A$6:$A$27,$A32) -> 24004046 | H32: =SUMIFS(I$6:I$27,$A$6:$A$27,$A32) -> 24803337 | I32: =SUMIFS(J$6:J$27,$A$6:$A$27,$A32) -> 25629663 | ... Q32: =SUMIFS(R$6:R$27,$A$6:$A$27,$A32) -> 4369598.1
A33: Lahore | B33: =SUMIFS(C$6:C$27,$A$6:$A$27,$A33) -> 13004135 | C33: =SUMIFS(D$6:D$27,$A$6:$A$27,$A33) -> 13342646 | D33: =SUMIFS(E$6:E$27,$A$6:$A$27,$A33) -> 13690236 | E33: =SUMIFS(F$6:F$27,$A$6:$A$27,$A33) -> 14047156 | F33: =SUMIFS(G$6:G$27,$A$6:$A$27,$A33) -> 14413663 | G33: =SUMIFS(H$6:H$27,$A$6:$A$27,$A33) -> 14790024 | H33: =SUMIFS(I$6:I$27,$A$6:$A$27,$A33) -> 15176510 | I33: =SUMIFS(J$6:J$27,$A$6:$A$27,$A33) -> 15573402 | ... Q33: =SUMIFS(R$6:R$27,$A$6:$A$27,$A33) -> 2429178.2
A34: Multan | B34: =SUMIFS(C$6:C$27,$A$6:$A$27,$A34) -> 5362305 | C34: =SUMIFS(D$6:D$27,$A$6:$A$27,$A34) -> 5472592.8 | D34: =SUMIFS(E$6:E$27,$A$6:$A$27,$A34) -> 5585173.9 | E34: =SUMIFS(F$6:F$27,$A$6:$A$27,$A34) -> 5700096.6 | F34: =SUMIFS(G$6:G$27,$A$6:$A$27,$A34) -> 5817410 | G34: =SUMIFS(H$6:H$27,$A$6:$A$27,$A34) -> 5937164.2 | H34: =SUMIFS(I$6:I$27,$A$6:$A$27,$A34) -> 6059410.7 | I34: =SUMIFS(J$6:J$27,$A$6:$A$27,$A34) -> 6184201.6 | ... Q34: =SUMIFS(R$6:R$27,$A$6:$A$27,$A34) -> 1022182.1
A35: Peshawar | B35: =SUMIFS(C$6:C$27,$A$6:$A$27,$A35) -> 4758762 | C35: =SUMIFS(D$6:D$27,$A$6:$A$27,$A35) -> 4840182.5 | D35: =SUMIFS(E$6:E$27,$A$6:$A$27,$A35) -> 4924169.3 | E35: =SUMIFS(F$6:F$27,$A$6:$A$27,$A35) -> 5010804.7 | F35: =SUMIFS(G$6:G$27,$A$6:$A$27,$A35) -> 5100174 | G35: =SUMIFS(H$6:H$27,$A$6:$A$27,$A35) -> 5192364.9 | H35: =SUMIFS(I$6:I$27,$A$6:$A$27,$A35) -> 5287468.3 | I35: =SUMIFS(J$6:J$27,$A$6:$A$27,$A35) -> 5385577.9 | ... Q35: =SUMIFS(R$6:R$27,$A$6:$A$27,$A35) -> 787554.58
A36: Islamabad | B36: =SUMIFS(C$6:C$27,$A$6:$A$27,$A36) -> 2363863 | C36: =SUMIFS(D$6:D$27,$A$6:$A$27,$A36) -> 2424288.6 | D36: =SUMIFS(E$6:E$27,$A$6:$A$27,$A36) -> 2486497.1 | E36: =SUMIFS(F$6:F$27,$A$6:$A$27,$A36) -> 2550546 | F36: =SUMIFS(G$6:G$27,$A$6:$A$27,$A36) -> 2616494.7 | G36: =SUMIFS(H$6:H$27,$A$6:$A$27,$A36) -> 2684404.5 | H36: =SUMIFS(I$6:I$27,$A$6:$A$27,$A36) -> 2754339 | I36: =SUMIFS(J$6:J$27,$A$6:$A$27,$A36) -> 2826363.8 | ... Q36: =SUMIFS(R$6:R$27,$A$6:$A$27,$A36) -> 495853.29

Sheet HyperMarkets
A1: HYPER MARKETS — THE DHA PHASE VIII TIER
A2: Seven enclaves with new bungalow stock and the highest selling prices. Each is priced as its own territory and subtracted from the region it sits inside, so nothing is counted twice. The built-house count is the one input to replace when DHA / Bahria / CDA supply plot data.
A4: Hyper market | B4: City | C4: Carved out of | D4: Dealership | E4: Area km² | F4: Built houses 2026 | G4: Growth | H4: SPP 2018 | I4: SPP 2026 | J4: SPP 2030
C5: The region this sits inside | D5: Parent club, if not sold separately | E5: Approximate developed area | F5: ESTIMATED occupied houses today. Replace with plot + occupancy data. | G5: Actively building, so growth is set at the cap | H5: Houses 8 years ago × sets per house | I5: Houses × sets per house | J5: Houses 4 years on × sets per house
A6: DHA Phase VIII + Sahil | B6: Karachi | C6: Karachi South | D6: KHI-1 | E6: 38 | F6: 12000 | G6: =Assumptions!$B$9 -> 0.035 | H6: =F6*(1+G6)^-8*Assumptions!$B$5 -> 10935.526 | I6: =F6*Assumptions!$B$5 -> 14400 | J6: =F6*(1+G6)^4*Assumptions!$B$5 -> 16524.331
A7: Bahria Town Karachi | B7: Karachi | C7: Malir | D7: KHI-4 | E7: 186 | F7: 9000 | G7: =Assumptions!$B$9 -> 0.035 | H7: =F7*(1+G7)^-8*Assumptions!$B$5 -> 8201.6448 | I7: =F7*Assumptions!$B$5 -> 10800 | J7: =F7*(1+G7)^4*Assumptions!$B$5 -> 12393.248
A8: DHA Lahore VII-IX + EME | B8: Lahore | C8: Raiwind | D8: LHE-1 | E8: 61 | F8: 14000 | G8: =Assumptions!$B$9 -> 0.035 | H8: =F8*(1+G8)^-8*Assumptions!$B$5 -> 12758.114 | I8: =F8*Assumptions!$B$5 -> 16800 | J8: =F8*(1+G8)^4*Assumptions!$B$5 -> 19278.386
A9: Bahria Town Lahore + Lake City | B9: Lahore | C9: Raiwind | D9: LHE-1 | E9: 45 | F9: 7000 | G9: =Assumptions!$B$9 -> 0.035 | H9: =F9*(1+G9)^-8*Assumptions!$B$5 -> 6379.0571 | I9: =F9*Assumptions!$B$5 -> 8400 | J9: =F9*(1+G9)^4*Assumptions!$B$5 -> 9639.1932
A10: DHA Islamabad + Bahria Enclave | B10: Islamabad | C10: ICT Rural belt | D10: ISB-1 | E10: 52 | F10: 8000 | G10: =Assumptions!$B$9 -> 0.035 | H10: =F10*(1+G10)^-8*Assumptions!$B$5 -> 7290.3509 | I10: =F10*Assumptions!$B$5 -> 9600 | J10: =F10*(1+G10)^4*Assumptions!$B$5 -> 11016.221
A11: Hayatabad Ph 6-7 + DHA Peshawar | B11: Peshawar | C11: Peshawar City | D11: PEW-1 | E11: 27 | F11: 5000 | G11: =Assumptions!$B$9 -> 0.035 | H11: =F11*(1+G11)^-8*Assumptions!$B$5 -> 4556.4693 | I11: =F11*Assumptions!$B$5 -> 6000 | J11: =F11*(1+G11)^4*Assumptions!$B$5 -> 6885.138
A12: DHA Multan | B12: Multan | C12: Multan Saddar | D12: MUX-1 | E12: 36 | F12: 4000 | G12: =Assumptions!$B$9 -> 0.035 | H12: =F12*(1+G12)^-8*Assumptions!$B$5 -> 3645.1755 | I12: =F12*Assumptions!$B$5 -> 4800 | J12: =F12*(1+G12)^4*Assumptions!$B$5 -> 5508.1104
B13: TOTAL — 7 hyper markets | E13: =SUM(E6:E12) -> 445 | F13: =SUM(F6:F12) -> 59000 | H13: =SUM(H6:H12) -> 53766.338 | I13: =SUM(I6:I12) -> 70800 | J13: =SUM(J6:J12) -> 81244.628

Sheet PumpPoints
A1: PUMP POINTS — ALL 29 TERRITORIES
A2: A pump point is one place a pump gets installed. A house is 1.2 of them; a flat is 1/40th. Regions here are net of any hyper market inside them. The last three columns multiply by the ASP tier to give 'revenue-weighted' points — a DHA point is worth several Orangi points.
A4: City | B4: Territory | C4: Type | D4: Tier | E4: Dealership | F4: Area km² | G4: HH 2026 | H4: SPP 2018 | I4: SPP 2026 | J4: SPP 2030 | K4: New build | L4: Replacement | M4: ASP × | N4: RPP base | O4: RPP new | P4: RPP repl
C5: Region or Hyper | D5: S/A/B/C | E5: Club code | F5: Net of carve-out | G5: Net of carve-out | H5: Pump points 8 years ago, net | I5: Pump points today, net | J5: End of term, net | K5: SPP 2030 - SPP 2026: points added by construction during the term | L5: SPP 2018 × term ÷ life: old pumps falling due inside the term | M5: Price multiplier from Assumptions | N5: SPP 2026 × ASP | O5: New build × ASP | P5: Replacement × ASP
A6: =CensusBase!A6 -> Karachi | B6: =CensusBase!B6 -> Karachi East | C6: Region | D6: =CensusBase!H6 -> B | E6: KHI-2 | F6: =CensusBase!C6-SUMIFS(HyperMarkets!$E$6:$E$12,HyperMarkets!$C$6:$C$12,B6) -> 139 | G6: =CensusBase!L6-SUMIFS(HyperMarkets!$F$6:$F$12,HyperMarkets!$C$6:$C$12,B6) -> 736967.03 | H6: =MAX(1,CensusBase!M6-SUMIFS(HyperMarkets!$H$6:$H$12,HyperMarkets!$C$6:$C$12,B6)) -> 244152.23 | I6: =MAX(1,CensusBase!N6-SUMIFS(HyperMarkets!$I$6:$I$12,HyperMarkets!$C$6:$C$12,B6)) -> 321501.87 | J6: =MAX(1,CensusBase!O6-SUMIFS(HyperMarkets!$J$6:$J$12,HyperMarkets!$C$6:$C$12,B6)) -> 368930.79 | K6: =J6-I6 -> 47428.92 | L6: =H6*Assumptions!$B$8/Assumptions!$B$7 -> 108512.1 | M6: =IF(D6="S",Assumptions!$B$18,IF(D6="A",Assumptions!$B$19,IF(D6="B",Assumptions!$B$20,Assumptions!$B$21))) -> 1.6 | N6: =I6*M6 -> 514402.98 | O6: =K6*M6 -> 75886.272 | P6: =L6*M6 -> 173619.36
A7: =CensusBase!A7 -> Karachi | B7: =CensusBase!B7 -> Karachi Central | C7: Region | D7: =CensusBase!H7 -> C | E7: KHI-3 | F7: =CensusBase!C7-SUMIFS(HyperMarkets!$E$6:$E$12,HyperMarkets!$C$6:$C$12,B7) -> 69 | G7: =CensusBase!L7-SUMIFS(HyperMarkets!$F$6:$F$12,HyperMarkets!$C$6:$C$12,B7) -> 730668.97 | H7: =MAX(1,CensusBase!M7-SUMIFS(HyperMarkets!$H$6:$H$12,HyperMarkets!$C$6:$C$12,B7)) -> 307263.95 | I7: =MAX(1,CensusBase!N7-SUMIFS(HyperMarkets!$I$6:$I$12,HyperMarkets!$C$6:$C$12,B7)) -> 404607.94 | J7: =MAX(1,CensusBase!O7-SUMIFS(HyperMarkets!$J$6:$J$12,HyperMarkets!$C$6:$C$12,B7)) -> 464296.92 | K7: =J7-I7 -> 59688.978 | L7: =H7*Assumptions!$B$8/Assumptions!$B$7 -> 136561.76 | M7: =IF(D7="S",Assumptions!$B$18,IF(D7="A",Assumptions!$B$19,IF(D7="B",Assumptions!$B$20,Assumptions!$B$21))) -> 1 | N7: =I7*M7 -> 404607.94 | O7: =K7*M7 -> 59688.978 | P7: =L7*M7 -> 136561.76
A8: =CensusBase!A8 -> Karachi | B8: =CensusBase!B8 -> Korangi | C8: Region | D8: =CensusBase!H8 -> C | E8: KHI-2 | F8: =CensusBase!C8-SUMIFS(HyperMarkets!$E$6:$E$12,HyperMarkets!$C$6:$C$12,B8) -> 108 | G8: =CensusBase!L8-SUMIFS(HyperMarkets!$F$6:$F$12,HyperMarkets!$C$6:$C$12,B8) -> 547214.63 | H8: =MAX(1,CensusBase!M8-SUMIFS(HyperMarkets!$H$6:$H$12,HyperMarkets!$C$6:$C$12,B8)) -> 308476.91 | I8: =MAX(1,CensusBase!N8-SUMIFS(HyperMarkets!$I$6:$I$12,HyperMarkets!$C$6:$C$12,B8)) -> 399466.68 | J8: =MAX(1,CensusBase!O8-SUMIFS(HyperMarkets!$J$6:$J$12,HyperMarkets!$C$6:$C$12,B8)) -> 454579.15 | K8: =J8-I8 -> 55112.471 | L8: =H8*Assumptions!$B$8/Assumptions!$B$7 -> 137100.85 | M8: =IF(D8="S",Assumptions!$B$18,IF(D8="A",Assumptions!$B$19,IF(D8="B",Assumptions!$B$20,Assumptions!$B$21))) -> 1 | N8: =I8*M8 -> 399466.68 | O8: =K8*M8 -> 55112.471 | P8: =L8*M8 -> 137100.85
A9: =CensusBase!A9 -> Karachi | B9: =CensusBase!B9 -> Karachi West | C9: Region | D9: =CensusBase!H9 -> C | E9: KHI-3 | F9: =CensusBase!C9-SUMIFS(HyperMarkets!$E$6:$E$12,HyperMarkets!$C$6:$C$12,B9) -> 370 | G9: =CensusBase!L9-SUMIFS(HyperMarkets!$F$6:$F$12,HyperMarkets!$C$6:$C$12,B9) -> 521171.32 | H9: =MAX(1,CensusBase!M9-SUMIFS(HyperMarkets!$H$6:$H$12,HyperMarkets!$C$6:$C$12,B9)) -> 335426.53 | I9: =MAX(1,CensusBase!N9-SUMIFS(HyperMarkets!$I$6:$I$12,HyperMarkets!$C$6:$C$12,B9)) -> 441692.69 | J9: =MAX(1,CensusBase!O9-SUMIFS(HyperMarkets!$J$6:$J$12,HyperMarkets!$C$6:$C$12,B9)) -> 506852.52 | K9: =J9-I9 -> 65159.831 | L9: =H9*Assumptions!$B$8/Assumptions!$B$7 -> 149078.46 | M9: =IF(D9="S",Assumptions!$B$18,IF(D9="A",Assumptions!$B$19,IF(D9="B",Assumptions!$B$20,Assumptions!$B$21))) -> 1 | N9: =I9*M9 -> 441692.69 | O9: =K9*M9 -> 65159.831 | P9: =L9*M9 -> 149078.46
A10: =CensusBase!A10 -> Karachi | B10: =CensusBase!B10 -> Malir | C10: Region | D10: =CensusBase!H10 -> B | E10: KHI-4 | F10: =CensusBase!C10-SUMIFS(HyperMarkets!$E$6:$E$12,HyperMarkets!$C$6:$C$12,B10) -> 1974 | G10: =CensusBase!L10-SUMIFS(HyperMarkets!$F$6:$F$12,HyperMarkets!$C$6:$C$12,B10) -> 464101.2 | H10: =MAX(1,CensusBase!M10-SUMIFS(HyperMarkets!$H$6:$H$12,HyperMarkets!$C$6:$C$12,B10)) -> 317394.51 | I10: =MAX(1,CensusBase!N10-SUMIFS(HyperMarkets!$I$6:$I$12,HyperMarkets!$C$6:$C$12,B10)) -> 417947.96 | J10: =MAX(1,CensusBase!O10-SUMIFS(HyperMarkets!$J$6:$J$12,HyperMarkets!$C$6:$C$12,B10)) -> 479604.9 | K10: =J10-I10 -> 61656.937 | L10: =H10*Assumptions!$B$8/Assumptions!$B$7 -> 141064.23 | M10: =IF(D10="S",Assumptions!$B$18,IF(D10="A",Assumptions!$B$19,IF(D10="B",Assumptions!$B$20,Assumptions!$B$21))) -> 1.6 | N10: =I10*M10 -> 668716.74 | O10: =K10*M10 -> 98651.1 | P10: =L10*M10 -> 225702.76
A11: =CensusBase!A11 -> Karachi | B11: =CensusBase!B11 -> Karachi South | C11: Region | D11: =CensusBase!H11 -> A | E11: KHI-1 | F11: =CensusBase!C11-SUMIFS(HyperMarkets!$E$6:$E$12,HyperMarkets!$C$6:$C$12,B11) -> 84 | G11: =CensusBase!L11-SUMIFS(HyperMarkets!$F$6:$F$12,HyperMarkets!$C$6:$C$12,B11) -> 466342.78 | H11: =MAX(1,CensusBase!M11-SUMIFS(HyperMarkets!$H$6:$H$12,HyperMarkets!$C$6:$C$12,B11)) -> 232902.1 | I11: =MAX(1,CensusBase!N11-SUMIFS(HyperMarkets!$I$6:$I$12,HyperMarkets!$C$6:$C$12,B11)) -> 306687.59 | J11: =MAX(1,CensusBase!O11-SUMIFS(HyperMarkets!$J$6:$J$12,HyperMarkets!$C$6:$C$12,B11)) -> 351931.06 | K11: =J11-I11 -> 45243.473 | L11: =H11*Assumptions!$B$8/Assumptions!$B$7 -> 103512.04 | M11: =IF(D11="S",Assumptions!$B$18,IF(D11="A",Assumptions!$B$19,IF(D11="B",Assumptions!$B$20,Assumptions!$B$21))) -> 3 | N11: =I11*M11 -> 920062.77 | O11: =K11*M11 -> 135730.42 | P11: =L11*M11 -> 310536.13
A12: =CensusBase!A12 -> Karachi | B12: =CensusBase!B12 -> Keamari | C12: Region | D12: =CensusBase!H12 -> C | E12: KHI-3 | F12: =CensusBase!C12-SUMIFS(HyperMarkets!$E$6:$E$12,HyperMarkets!$C$6:$C$12,B12) -> 559 | G12: =CensusBase!L12-SUMIFS(HyperMarkets!$F$6:$F$12,HyperMarkets!$C$6:$C$12,B12) -> 343622.57 | H12: =MAX(1,CensusBase!M12-SUMIFS(HyperMarkets!$H$6:$H$12,HyperMarkets!$C$6:$C$12,B12)) -> 247311.48 | I12: =MAX(1,CensusBase!N12-SUMIFS(HyperMarkets!$I$6:$I$12,HyperMarkets!$C$6:$C$12,B12)) -> 291220.13 | J12: =MAX(1,CensusBase!O12-SUMIFS(HyperMarkets!$J$6:$J$12,HyperMarkets!$C$6:$C$12,B12)) -> 316016.63 | K12: =J12-I12 -> 24796.506 | L12: =H12*Assumptions!$B$8/Assumptions!$B$7 -> 109916.21 | M12: =IF(D12="S",Assumptions!$B$18,IF(D12="A",Assumptions!$B$19,IF(D12="B",Assumptions!$B$20,Assumptions!$B$21))) -> 1 | N12: =I12*M12 -> 291220.13 | O12: =K12*M12 -> 24796.506 | P12: =L12*M12 -> 109916.21
A13: =CensusBase!A13 -> Lahore | B13: =CensusBase!B13 -> Lahore City | C13: Region | D13: =CensusBase!H13 -> C | E13: LHE-2 | F13: =CensusBase!C13-SUMIFS(HyperMarkets!$E$6:$E$12,HyperMarkets!$C$6:$C$12,B13) -> 214 | G13: =CensusBase!L13-SUMIFS(HyperMarkets!$F$6:$F$12,HyperMarkets!$C$6:$C$12,B13) -> 674724.53 | H13: =MAX(1,CensusBase!M13-SUMIFS(HyperMarkets!$H$6:$H$12,HyperMarkets!$C$6:$C$12,B13)) -> 518724.26 | I13: =MAX(1,CensusBase!N13-SUMIFS(HyperMarkets!$I$6:$I$12,HyperMarkets!$C$6:$C$12,B13)) -> 611469.1 | J13: =MAX(1,CensusBase!O13-SUMIFS(HyperMarkets!$J$6:$J$12,HyperMarkets!$C$6:$C$12,B13)) -> 663885.98 | K13: =J13-I13 -> 52416.876 | L13: =H13*Assumptions!$B$8/Assumptions!$B$7 -> 230544.12 | M13: =IF(D13="S",Assumptions!$B$18,IF(D13="A",Assumptions!$B$19,IF(D13="B",Assumptions!$B$20,Assumptions!$B$21))) -> 1 | N13: =I13*M13 -> 611469.1 | O13: =K13*M13 -> 52416.876 | P13: =L13*M13 -> 230544.12
A14: =CensusBase!A14 -> Lahore | B14: =CensusBase!B14 -> Model Town | C14: Region | D14: =CensusBase!H14 -> B | E14: LHE-3 | F14: =CensusBase!C14-SUMIFS(HyperMarkets!$E$6:$E$12,HyperMarkets!$C$6:$C$12,B14) -> 353 | G14: =CensusBase!L14-SUMIFS(HyperMarkets!$F$6:$F$12,HyperMarkets!$C$6:$C$12,B14) -> 546025.74 | H14: =MAX(1,CensusBase!M14-SUMIFS(HyperMarkets!$H$6:$H$12,HyperMarkets!$C$6:$C$12,B14)) -> 364380.02 | I14: =MAX(1,CensusBase!N14-SUMIFS(HyperMarkets!$I$6:$I$12,HyperMarkets!$C$6:$C$12,B14)) -> 462756.81 | J14: =MAX(1,CensusBase!O14-SUMIFS(HyperMarkets!$J$6:$J$12,HyperMarkets!$C$6:$C$12,B14)) -> 521497.17 | K14: =J14-I14 -> 58740.36 | L14: =H14*Assumptions!$B$8/Assumptions!$B$7 -> 161946.67 | M14: =IF(D14="S",Assumptions!$B$18,IF(D14="A",Assumptions!$B$19,IF(D14="B",Assumptions!$B$20,Assumptions!$B$21))) -> 1.6 | N14: =I14*M14 -> 740410.9 | O14: =K14*M14 -> 93984.576 | P14: =L14*M14 -> 259114.68
A15: =CensusBase!A15 -> Lahore | B15: =CensusBase!B15 -> Shalimar | C15: Region | D15: =CensusBase!H15 -> C | E15: LHE-2 | F15: =CensusBase!C15-SUMIFS(HyperMarkets!$E$6:$E$12,HyperMarkets!$C$6:$C$12,B15) -> 272 | G15: =CensusBase!L15-SUMIFS(HyperMarkets!$F$6:$F$12,HyperMarkets!$C$6:$C$12,B15) -> 458505.8 | H15: =MAX(1,CensusBase!M15-SUMIFS(HyperMarkets!$H$6:$H$12,HyperMarkets!$C$6:$C$12,B15)) -> 336916.73 | I15: =MAX(1,CensusBase!N15-SUMIFS(HyperMarkets!$I$6:$I$12,HyperMarkets!$C$6:$C$12,B15)) -> 415520.89 | J15: =MAX(1,CensusBase!O15-SUMIFS(HyperMarkets!$J$6:$J$12,HyperMarkets!$C$6:$C$12,B15)) -> 461453.56 | K15: =J15-I15 -> 45932.671 | L15: =H15*Assumptions!$B$8/Assumptions!$B$7 -> 149740.77 | M15: =IF(D15="S",Assumptions!$B$18,IF(D15="A",Assumptions!$B$19,IF(D15="B",Assumptions!$B$20,Assumptions!$B$21))) -> 1 | N15: =I15*M15 -> 415520.89 | O15: =K15*M15 -> 45932.671 | P15: =L15*M15 -> 149740.77
A16: =CensusBase!A16 -> Lahore | B16: =CensusBase!B16 -> Lahore Cantt | C16: Region | D16: =CensusBase!H16 -> A | E16: LHE-1 | F16: =CensusBase!C16-SUMIFS(HyperMarkets!$E$6:$E$12,HyperMarkets!$C$6:$C$12,B16) -> 466 | G16: =CensusBase!L16-SUMIFS(HyperMarkets!$F$6:$F$12,HyperMarkets!$C$6:$C$12,B16) -> 321519.18 | H16: =MAX(1,CensusBase!M16-SUMIFS(HyperMarkets!$H$6:$H$12,HyperMarkets!$C$6:$C$12,B16)) -> 271747.02 | I16: =MAX(1,CensusBase!N16-SUMIFS(HyperMarkets!$I$6:$I$12,HyperMarkets!$C$6:$C$12,B16)) -> 329155.26 | J16: =MAX(1,CensusBase!O16-SUMIFS(HyperMarkets!$J$6:$J$12,HyperMarkets!$C$6:$C$12,B16)) -> 362258.69 | K16: =J16-I16 -> 33103.424 | L16: =H16*Assumptions!$B$8/Assumptions!$B$7 -> 120776.45 | M16: =IF(D16="S",Assumptions!$B$18,IF(D16="A",Assumptions!$B$19,IF(D16="B",Assumptions!$B$20,Assumptions!$B$21))) -> 3 | N16: =I16*M16 -> 987465.79 | O16: =K16*M16 -> 99310.272 | P16: =L16*M16 -> 362329.36
A17: =CensusBase!A17 -> Lahore | B17: =CensusBase!B17 -> Raiwind | C17: Region | D17: =CensusBase!H17 -> B | E17: LHE-1 | F17: =CensusBase!C17-SUMIFS(HyperMarkets!$E$6:$E$12,HyperMarkets!$C$6:$C$12,B17) -> 361 | G17: =CensusBase!L17-SUMIFS(HyperMarkets!$F$6:$F$12,HyperMarkets!$C$6:$C$12,B17) -> 169178.03 | H17: =MAX(1,CensusBase!M17-SUMIFS(HyperMarkets!$H$6:$H$12,HyperMarkets!$C$6:$C$12,B17)) -> 128716.27 | I17: =MAX(1,CensusBase!N17-SUMIFS(HyperMarkets!$I$6:$I$12,HyperMarkets!$C$6:$C$12,B17)) -> 169494.75 | J17: =MAX(1,CensusBase!O17-SUMIFS(HyperMarkets!$J$6:$J$12,HyperMarkets!$C$6:$C$12,B17)) -> 194499.13 | K17: =J17-I17 -> 25004.375 | L17: =H17*Assumptions!$B$8/Assumptions!$B$7 -> 57207.233 | M17: =IF(D17="S",Assumptions!$B$18,IF(D17="A",Assumptions!$B$19,IF(D17="B",Assumptions!$B$20,Assumptions!$B$21))) -> 1.6 | N17: =I17*M17 -> 271191.61 | O17: =K17*M17 -> 40006.999 | P17: =L17*M17 -> 91531.573
... A27: =CensusBase!A27 -> Islamabad | B27: =CensusBase!B27 -> ICT Urban | C27: Region | D27: =CensusBase!H27 -> A | E27: ISB-1 | F27: =CensusBase!C27-SUMIFS(HyperMarkets!$E$6:$E$12,HyperMarkets!$C$6:$C$12,B27) -> 206 | G27: =CensusBase!L27-SUMIFS(HyperMarkets!$F$6:$F$12,HyperMarkets!$C$6:$C$12,B27) -> 203353.52 | H27: =MAX(1,CensusBase!M27-SUMIFS(HyperMarkets!$H$6:$H$12,HyperMarkets!$C$6:$C$12,B27)) -> 131902.86 | I27: =MAX(1,CensusBase!N27-SUMIFS(HyperMarkets!$I$6:$I$12,HyperMarkets!$C$6:$C$12,B27)) -> 148448.07 | J27: =MAX(1,CensusBase!O27-SUMIFS(HyperMarkets!$J$6:$J$12,HyperMarkets!$C$6:$C$12,B27)) -> 157483.38 | K27: =J27-I27 -> 9035.3105 | L27: =H27*Assumptions!$B$8/Assumptions!$B$7 -> 58623.492 | M27: =IF(D27="S",Assumptions!$B$18,IF(D27="A",Assumptions!$B$19,IF(D27="B",Assumptions!$B$20,Assumptions!$B$21))) -> 3 | N27: =I27*M27 -> 445344.21 | O27: =K27*M27 -> 27105.931 | P27: =L27*M27 -> 175870.48
A28: =HyperMarkets!B6 -> Karachi | B28: =HyperMarkets!A6 -> DHA Phase VIII + Sahil | C28: Hyper | D28: S | E28: =HyperMarkets!D6 -> KHI-1 | F28: =HyperMarkets!E6 -> 38 | G28: =HyperMarkets!F6 -> 12000 | H28: =HyperMarkets!H6 -> 10935.526 | I28: =HyperMarkets!I6 -> 14400 | J28: =HyperMarkets!J6 -> 16524.331 | K28: =J28-I28 -> 2124.3312 | L28: =H28*Assumptions!$B$8/Assumptions!$B$7 -> 4860.234 | M28: =IF(D28="S",Assumptions!$B$18,IF(D28="A",Assumptions!$B$19,IF(D28="B",Assumptions!$B$20,Assumptions!$B$21))) -> 8 | N28: =I28*M28 -> 115200 | O28: =K28*M28 -> 16994.65 | P28: =L28*M28 -> 38881.872
A29: =HyperMarkets!B7 -> Karachi | B29: =HyperMarkets!A7 -> Bahria Town Karachi | C29: Hyper | D29: S | E29: =HyperMarkets!D7 -> KHI-4 | F29: =HyperMarkets!E7 -> 186 | G29: =HyperMarkets!F7 -> 9000 | H29: =HyperMarkets!H7 -> 8201.6448 | I29: =HyperMarkets!I7 -> 10800 | J29: =HyperMarkets!J7 -> 12393.248 | K29: =J29-I29 -> 1593.2484 | L29: =H29*Assumptions!$B$8/Assumptions!$B$7 -> 3645.1755 | M29: =IF(D29="S",Assumptions!$B$18,IF(D29="A",Assumptions!$B$19,IF(D29="B",Assumptions!$B$20,Assumptions!$B$21))) -> 8 | N29: =I29*M29 -> 86400 | O29: =K29*M29 -> 12745.987 | P29: =L29*M29 -> 29161.404
A30: =HyperMarkets!B8 -> Lahore | B30: =HyperMarkets!A8 -> DHA Lahore VII-IX + EME | C30: Hyper | D30: S | E30: =HyperMarkets!D8 -> LHE-1 | F30: =HyperMarkets!E8 -> 61 | G30: =HyperMarkets!F8 -> 14000 | H30: =HyperMarkets!H8 -> 12758.114 | I30: =HyperMarkets!I8 -> 16800 | J30: =HyperMarkets!J8 -> 19278.386 | K30: =J30-I30 -> 2478.3864 | L30: =H30*Assumptions!$B$8/Assumptions!$B$7 -> 5670.273 | M30: =IF(D30="S",Assumptions!$B$18,IF(D30="A",Assumptions!$B$19,IF(D30="B",Assumptions!$B$20,Assumptions!$B$21))) -> 8 | N30: =I30*M30 -> 134400 | O30: =K30*M30 -> 19827.091 | P30: =L30*M30 -> 45362.184
A31: =HyperMarkets!B9 -> Lahore | B31: =HyperMarkets!A9 -> Bahria Town Lahore + Lake City | C31: Hyper | D31: S | E31: =HyperMarkets!D9 -> LHE-1 | F31: =HyperMarkets!E9 -> 45 | G31: =HyperMarkets!F9 -> 7000 | H31: =HyperMarkets!H9 -> 6379.0571 | I31: =HyperMarkets!I9 -> 8400 | J31: =HyperMarkets!J9 -> 9639.1932 | K31: =J31-I31 -> 1239.1932 | L31: =H31*Assumptions!$B$8/Assumptions!$B$7 -> 2835.1365 | M31: =IF(D31="S",Assumptions!$B$18,IF(D31="A",Assumptions!$B$19,IF(D31="B",Assumptions!$B$20,Assumptions!$B$21))) -> 8 | N31: =I31*M31 -> 67200 | O31: =K31*M31 -> 9913.5456 | P31: =L31*M31 -> 22681.092
A32: =HyperMarkets!B10 -> Islamabad | B32: =HyperMarkets!A10 -> DHA Islamabad + Bahria Enclave | C32: Hyper | D32: S | E32: =HyperMarkets!D10 -> ISB-1 | F32: =HyperMarkets!E10 -> 52 | G32: =HyperMarkets!F10 -> 8000 | H32: =HyperMarkets!H10 -> 7290.3509 | I32: =HyperMarkets!I10 -> 9600 | J32: =HyperMarkets!J10 -> 11016.221 | K32: =J32-I32 -> 1416.2208 | L32: =H32*Assumptions!$B$8/Assumptions!$B$7 -> 3240.156 | M32: =IF(D32="S",Assumptions!$B$18,IF(D32="A",Assumptions!$B$19,IF(D32="B",Assumptions!$B$20,Assumptions!$B$21))) -> 8 | N32: =I32*M32 -> 76800 | O32: =K32*M32 -> 11329.766 | P32: =L32*M32 -> 25921.248
A33: =HyperMarkets!B11 -> Peshawar | B33: =HyperMarkets!A11 -> Hayatabad Ph 6-7 + DHA Peshawar | C33: Hyper | D33: S | E33: =HyperMarkets!D11 -> PEW-1 | F33: =HyperMarkets!E11 -> 27 | G33: =HyperMarkets!F11 -> 5000 | H33: =HyperMarkets!H11 -> 4556.4693 | I33: =HyperMarkets!I11 -> 6000 | J33: =HyperMarkets!J11 -> 6885.138 | K33: =J33-I33 -> 885.138 | L33: =H33*Assumptions!$B$8/Assumptions!$B$7 -> 2025.0975 | M33: =IF(D33="S",Assumptions!$B$18,IF(D33="A",Assumptions!$B$19,IF(D33="B",Assumptions!$B$20,Assumptions!$B$21))) -> 8 | N33: =I33*M33 -> 48000 | O33: =K33*M33 -> 7081.104 | P33: =L33*M33 -> 16200.78
A34: =HyperMarkets!B12 -> Multan | B34: =HyperMarkets!A12 -> DHA Multan | C34: Hyper | D34: S | E34: =HyperMarkets!D12 -> MUX-1 | F34: =HyperMarkets!E12 -> 36 | G34: =HyperMarkets!F12 -> 4000 | H34: =HyperMarkets!H12 -> 3645.1755 | I34: =HyperMarkets!I12 -> 4800 | J34: =HyperMarkets!J12 -> 5508.1104 | K34: =J34-I34 -> 708.1104 | L34: =H34*Assumptions!$B$8/Assumptions!$B$7 -> 1620.078 | M34: =IF(D34="S",Assumptions!$B$18,IF(D34="A",Assumptions!$B$19,IF(D34="B",Assumptions!$B$20,Assumptions!$B$21))) -> 8 | N34: =I34*M34 -> 38400 | O34: =K34*M34 -> 5664.8832 | P34: =L34*M34 -> 12960.624
B35: TOTAL — 29 territories | F35: =SUM(F6:F34) -> 11443 | G35: =SUM(G6:G34) -> 8143804 | H35: =SUM(H6:H34) -> 5403067.8 | I35: =SUM(I6:I34) -> 6692331.3 | J35: =SUM(J6:J34) -> 7460577.8 | K35: =SUM(K6:K34) -> 768246.47 | L35: =SUM(L6:L34) -> 2401363.5 | N35: =SUM(N6:N34) -> 10120132 | O35: =SUM(O6:O34) -> 1173441.3 | P35: =SUM(P6:P34) -> 3624507

Sheet FeeSchedule
A1: FEE SCHEDULE — ANCHORED ON ISLAMABAD AT Rs 1 Cr
A2: Fee Units are a score out of 100 across all 29 territories. A territory's fee is its units × the rate, and the rate is whatever makes the anchor territory hit its anchor price. Column H is the chosen schedule (Islamabad whole city = Rs 1 Cr). Column J shows the higher DHA anchor for comparison only.
A4: City | B4: Territory | C4: Type | D4: Tier | E4: Dealership | F4: Fee Units | G4: Share of national | H4: FEE — CHOSEN (PKR) | I4: Chosen Rs Cr | J4: Fee — Alt anchor (PKR) | K4: Alt Rs Cr | L4: Active fee (PKR) | M4: Inventory credit (PKR) | N4: Inventory units
F5: 45% new-build share + 35% replacement share + 15% base share + 5% area share, each measured against the national total, ×100 | G5: Fee Units ÷ 100 | H5: Units × chosen rate (Islamabad Rs 1 Cr) | I5: Same in crore | J5: Units × alternative rate (DHA Rs 1.5 Cr) | K5: Same in crore | L5: Whichever scenario is active on Assumptions | M5: Active fee × credit fraction — stock the dealer receives | N5: Credit ÷ pump price — how many pumps that is
A6: =PumpPoints!A6 -> Karachi | B6: =PumpPoints!B6 -> Karachi East | C6: =PumpPoints!C6 -> Region | D6: =PumpPoints!D6 -> B | E6: =PumpPoints!E6 -> KHI-2 | F6: =100*(Assumptions!$B$30*PumpPoints!O6/PumpPoints!$O$35+Assumptions!$B$31*PumpPoints!P6/PumpPoints!$P$35+Assumptions!$B$32*PumpPoints!N6/PumpPoints!$N$35+Assumptions!$B$33*PumpPoints!F6/PumpPoints!$F$35) -> 5.4098769 | G6: =F6/100 -> 0.054098769 | H6: =F6*Assumptions!$B$42 -> 5724944.4 | I6: =H6/10000000 -> 0.57249444 | J6: =F6*Assumptions!$B$43 -> 66813983 | K6: =J6/10000000 -> 6.6813983 | L6: =F6*Assumptions!$B$44 -> 5724944.4 | M6: =L6*Assumptions!$B$14 -> 2862472.2 | N6: =M6/Assumptions!$B$12 -> 22.899778
A7: =PumpPoints!A7 -> Karachi | B7: =PumpPoints!B7 -> Karachi Central | C7: =PumpPoints!C7 -> Region | D7: =PumpPoints!D7 -> C | E7: =PumpPoints!E7 -> KHI-3 | F7: =100*(Assumptions!$B$30*PumpPoints!O7/PumpPoints!$O$35+Assumptions!$B$31*PumpPoints!P7/PumpPoints!$P$35+Assumptions!$B$32*PumpPoints!N7/PumpPoints!$N$35+Assumptions!$B$33*PumpPoints!F7/PumpPoints!$F$35) -> 4.2375608 | G7: =F7/100 -> 0.042375608 | H7: =F7*Assumptions!$B$42 -> 4484353.5 | I7: =H7/10000000 -> 0.44843535 | J7: =F7*Assumptions!$B$43 -> 52335446 | K7: =J7/10000000 -> 5.2335446 | L7: =F7*Assumptions!$B$44 -> 4484353.5 | M7: =L7*Assumptions!$B$14 -> 2242176.7 | N7: =M7/Assumptions!$B$12 -> 17.937414
A8: =PumpPoints!A8 -> Karachi | B8: =PumpPoints!B8 -> Korangi | C8: =PumpPoints!C8 -> Region | D8: =PumpPoints!D8 -> C | E8: =PumpPoints!E8 -> KHI-2 | F8: =100*(Assumptions!$B$30*PumpPoints!O8/PumpPoints!$O$35+Assumptions!$B$31*PumpPoints!P8/PumpPoints!$P$35+Assumptions!$B$32*PumpPoints!N8/PumpPoints!$N$35+Assumptions!$B$33*PumpPoints!F8/PumpPoints!$F$35) -> 4.0766839 | G8: =F8/100 -> 0.040766839 | H8: =F8*Assumptions!$B$42 -> 4314107.2 | I8: =H8/10000000 -> 0.43141072 | J8: =F8*Assumptions!$B$43 -> 50348556 | K8: =J8/10000000 -> 5.0348556 | L8: =F8*Assumptions!$B$44 -> 4314107.2 | M8: =L8*Assumptions!$B$14 -> 2157053.6 | N8: =M8/Assumptions!$B$12 -> 17.256429
A9: =PumpPoints!A9 -> Karachi | B9: =PumpPoints!B9 -> Karachi West | C9: =PumpPoints!C9 -> Region | D9: =PumpPoints!D9 -> C | E9: =PumpPoints!E9 -> KHI-3 | F9: =100*(Assumptions!$B$30*PumpPoints!O9/PumpPoints!$O$35+Assumptions!$B$31*PumpPoints!P9/PumpPoints!$P$35+Assumptions!$B$32*PumpPoints!N9/PumpPoints!$N$35+Assumptions!$B$33*PumpPoints!F9/PumpPoints!$F$35) -> 4.7547168 | G9: =F9/100 -> 0.047547168 | H9: =F9*Assumptions!$B$42 -> 5031628.2 | I9: =H9/10000000 -> 0.50316282 | J9: =F9*Assumptions!$B$43 -> 58722513 | K9: =J9/10000000 -> 5.8722513 | L9: =F9*Assumptions!$B$44 -> 5031628.2 | M9: =L9*Assumptions!$B$14 -> 2515814.1 | N9: =M9/Assumptions!$B$12 -> 20.126513
A10: =PumpPoints!A10 -> Karachi | B10: =PumpPoints!B10 -> Malir | C10: =PumpPoints!C10 -> Region | D10: =PumpPoints!D10 -> B | E10: =PumpPoints!E10 -> KHI-4 | F10: =100*(Assumptions!$B$30*PumpPoints!O10/PumpPoints!$O$35+Assumptions!$B$31*PumpPoints!P10/PumpPoints!$P$35+Assumptions!$B$32*PumpPoints!N10/PumpPoints!$N$35+Assumptions!$B$33*PumpPoints!F10/PumpPoints!$F$35) -> 7.8163452 | G10: =F10/100 -> 0.078163452 | H10: =F10*Assumptions!$B$42 -> 8271563.8 | I10: =H10/10000000 -> 0.82715638 | J10: =F10*Assumptions!$B$43 -> 96534758 | K10: =J10/10000000 -> 9.6534758 | L10: =F10*Assumptions!$B$44 -> 8271563.8 | M10: =L10*Assumptions!$B$14 -> 4135781.9 | N10: =M10/Assumptions!$B$12 -> 33.086255
A11: =PumpPoints!A11 -> Karachi | B11: =PumpPoints!B11 -> Karachi South | C11: =PumpPoints!C11 -> Region | D11: =PumpPoints!D11 -> A | E11: =PumpPoints!E11 -> KHI-1 | F11: =100*(Assumptions!$B$30*PumpPoints!O11/PumpPoints!$O$35+Assumptions!$B$31*PumpPoints!P11/PumpPoints!$P$35+Assumptions!$B$32*PumpPoints!N11/PumpPoints!$N$35+Assumptions!$B$33*PumpPoints!F11/PumpPoints!$F$35) -> 9.6041939 | G11: =F11/100 -> 0.096041939 | H11: =F11*Assumptions!$B$42 -> 10163536 | I11: =H11/10000000 -> 1.0163536 | J11: =F11*Assumptions!$B$43 -> 1.1861535e+08 | K11: =J11/10000000 -> 11.861535 | L11: =F11*Assumptions!$B$44 -> 10163536 | M11: =L11*Assumptions!$B$14 -> 5081767.8 | N11: =M11/Assumptions!$B$12 -> 40.654142
A12: =PumpPoints!A12 -> Karachi | B12: =PumpPoints!B12 -> Keamari | C12: =PumpPoints!C12 -> Region | D12: =PumpPoints!D12 -> C | E12: =PumpPoints!E12 -> KHI-3 | F12: =100*(Assumptions!$B$30*PumpPoints!O12/PumpPoints!$O$35+Assumptions!$B$31*PumpPoints!P12/PumpPoints!$P$35+Assumptions!$B$32*PumpPoints!N12/PumpPoints!$N$35+Assumptions!$B$33*PumpPoints!F12/PumpPoints!$F$35) -> 2.688218 | G12: =F12/100 -> 0.02688218 | H12: =F12*Assumptions!$B$42 -> 2844778 | I12: =H12/10000000 -> 0.2844778 | J12: =F12*Assumptions!$B$43 -> 33200488 | K12: =J12/10000000 -> 3.3200488 | L12: =F12*Assumptions!$B$44 -> 2844778 | M12: =L12*Assumptions!$B$14 -> 1422389 | N12: =M12/Assumptions!$B$12 -> 11.379112
A13: =PumpPoints!A13 -> Lahore | B13: =PumpPoints!B13 -> Lahore City | C13: =PumpPoints!C13 -> Region | D13: =PumpPoints!D13 -> C | E13: =PumpPoints!E13 -> LHE-2 | F13: =100*(Assumptions!$B$30*PumpPoints!O13/PumpPoints!$O$35+Assumptions!$B$31*PumpPoints!P13/PumpPoints!$P$35+Assumptions!$B$32*PumpPoints!N13/PumpPoints!$N$35+Assumptions!$B$33*PumpPoints!F13/PumpPoints!$F$35) -> 5.2361901 | G13: =F13/100 -> 0.052361901 | H13: =F13*Assumptions!$B$42 -> 5541142.2 | I13: =H13/10000000 -> 0.55411422 | J13: =F13*Assumptions!$B$43 -> 64668886 | K13: =J13/10000000 -> 6.4668886 | L13: =F13*Assumptions!$B$44 -> 5541142.2 | M13: =L13*Assumptions!$B$14 -> 2770571.1 | N13: =M13/Assumptions!$B$12 -> 22.164569
A14: =PumpPoints!A14 -> Lahore | B14: =PumpPoints!B14 -> Model Town | C14: =PumpPoints!C14 -> Region | D14: =PumpPoints!D14 -> B | E14: =PumpPoints!E14 -> LHE-3 | F14: =100*(Assumptions!$B$30*PumpPoints!O14/PumpPoints!$O$35+Assumptions!$B$31*PumpPoints!P14/PumpPoints!$P$35+Assumptions!$B$32*PumpPoints!N14/PumpPoints!$N$35+Assumptions!$B$33*PumpPoints!F14/PumpPoints!$F$35) -> 7.3580029 | G14: =F14/100 -> 0.073580029 | H14: =F14*Assumptions!$B$42 -> 7786527.9 | I14: =H14/10000000 -> 0.77865279 | J14: =F14*Assumptions!$B$43 -> 90874061 | K14: =J14/10000000 -> 9.0874061 | L14: =F14*Assumptions!$B$44 -> 7786527.9 | M14: =L14*Assumptions!$B$14 -> 3893264 | N14: =M14/Assumptions!$B$12 -> 31.146112
A15: =PumpPoints!A15 -> Lahore | B15: =PumpPoints!B15 -> Shalimar | C15: =PumpPoints!C15 -> Region | D15: =PumpPoints!D15 -> C | E15: =PumpPoints!E15 -> LHE-2 | F15: =100*(Assumptions!$B$30*PumpPoints!O15/PumpPoints!$O$35+Assumptions!$B$31*PumpPoints!P15/PumpPoints!$P$35+Assumptions!$B$32*PumpPoints!N15/PumpPoints!$N$35+Assumptions!$B$33*PumpPoints!F15/PumpPoints!$F$35) -> 3.9421623 | G15: =F15/100 -> 0.039421623 | H15: =F15*Assumptions!$B$42 -> 4171751.2 | I15: =H15/10000000 -> 0.41717512 | J15: =F15*Assumptions!$B$43 -> 48687165 | K15: =J15/10000000 -> 4.8687165 | L15: =F15*Assumptions!$B$44 -> 4171751.2 | M15: =L15*Assumptions!$B$14 -> 2085875.6 | N15: =M15/Assumptions!$B$12 -> 16.687005
A16: =PumpPoints!A16 -> Lahore | B16: =PumpPoints!B16 -> Lahore Cantt | C16: =PumpPoints!C16 -> Region | D16: =PumpPoints!D16 -> A | E16: =PumpPoints!E16 -> LHE-1 | F16: =100*(Assumptions!$B$30*PumpPoints!O16/PumpPoints!$O$35+Assumptions!$B$31*PumpPoints!P16/PumpPoints!$P$35+Assumptions!$B$32*PumpPoints!N16/PumpPoints!$N$35+Assumptions!$B$33*PumpPoints!F16/PumpPoints!$F$35) -> 8.9744862 | G16: =F16/100 -> 0.089744862 | H16: =F16*Assumptions!$B$42 -> 9497154.2 | I16: =H16/10000000 -> 0.94971542 | J16: =F16*Assumptions!$B$43 -> 1.1083823e+08 | K16: =J16/10000000 -> 11.083823 | L16: =F16*Assumptions!$B$44 -> 9497154.2 | M16: =L16*Assumptions!$B$14 -> 4748577.1 | N16: =M16/Assumptions!$B$12 -> 37.988617
A17: =PumpPoints!A17 -> Lahore | B17: =PumpPoints!B17 -> Raiwind | C17: =PumpPoints!C17 -> Region | D17: =PumpPoints!D17 -> B | E17: =PumpPoints!E17 -> LHE-1 | F17: =100*(Assumptions!$B$30*PumpPoints!O17/PumpPoints!$O$35+Assumptions!$B$31*PumpPoints!P17/PumpPoints!$P$35+Assumptions!$B$32*PumpPoints!N17/PumpPoints!$N$35+Assumptions!$B$33*PumpPoints!F17/PumpPoints!$F$35) -> 2.9777884 | G17: =F17/100 -> 0.029777884 | H17: =F17*Assumptions!$B$42 -> 3151212.7 | I17: =H17/10000000 -> 0.31512127 | J17: =F17*Assumptions!$B$43 -> 36776789 | K17: =J17/10000000 -> 3.6776789 | L17: =F17*Assumptions!$B$44 -> 3151212.7 | M17: =L17*Assumptions!$B$14 -> 1575606.4 | N17: =M17/Assumptions!$B$12 -> 12.604851
... A34: =PumpPoints!A34 -> Multan | B34: =PumpPoints!B34 -> DHA Multan | C34: =PumpPoints!C34 -> Hyper | D34: =PumpPoints!D34 -> S | E34: =PumpPoints!E34 -> MUX-1 | F34: =100*(Assumptions!$B$30*PumpPoints!O34/PumpPoints!$O$35+Assumptions!$B$31*PumpPoints!P34/PumpPoints!$P$35+Assumptions!$B$32*PumpPoints!N34/PumpPoints!$N$35+Assumptions!$B$33*PumpPoints!F34/PumpPoints!$F$35) -> 0.41504162 | G34: =F34/100 -> 0.0041504162 | H34: =F34*Assumptions!$B$42 -> 439213.36 | I34: =H34/10000000 -> 0.043921336 | J34: =F34*Assumptions!$B$43 -> 5125917.7 | K34: =J34/10000000 -> 0.51259177 | L34: =F34*Assumptions!$B$44 -> 439213.36 | M34: =L34*Assumptions!$B$14 -> 219606.68 | N34: =M34/Assumptions!$B$12 -> 1.7568534
B35: TOTAL network | F35: =SUM(F6:F34) -> 100 | G35: =SUM(G6:G34) -> 1 | H35: =SUM(H6:H34) -> 1.0582393e+08 | I35: =SUM(I6:I34) -> 10.582393 | J35: =SUM(J6:J34) -> 1.235037e+09 | K35: =SUM(K6:K34) -> 123.5037 | L35: =SUM(L6:L34) -> 1.0582393e+08 | M35: =SUM(M6:M34) -> 52911966 | N35: =SUM(N6:N34) -> 423.29573

Sheet Quotas
A1: QUOTAS — HOW MANY PUMPS EACH DEALER SHOULD SELL
A2: The quota comes from the market, not from the fee: how many pumps get bought in that territory each year, times a realistic Grundfos share. Year one ramps up because a new dealer cannot hit full speed in their first quarter.
A4: City | B4: Territory | C4: Tier | D4: Dealership | E4: Addressable / yr | F4: Grundfos share | G4: Units / yr | H4: Steady / qtr | I4: Y1 Q1 | J4: Y1 Q2 | K4: Y1 Q3 | L4: Y1 Q4 | M4: Year-1 units
E5: (New build + replacement) ÷ term: pumps bought in this territory per year, all brands | F5: Share Grundfos can realistically win, from Assumptions | G5: Addressable × share | H5: Units / yr ÷ 4 | I5: Steady × ramp | M5: Sum of the four quarters
A6: =PumpPoints!A6 -> Karachi | B6: =PumpPoints!B6 -> Karachi East | C6: =PumpPoints!D6 -> B | D6: =PumpPoints!E6 -> KHI-2 | E6: =(PumpPoints!K6+PumpPoints!L6)/Assumptions!$B$8 -> 38985.256 | F6: =IF(C6="S",Assumptions!$B$24,IF(C6="A",Assumptions!$B$25,IF(C6="B",Assumptions!$B$26,Assumptions!$B$27))) -> 0.015 | G6: =E6*F6 -> 584.77884 | H6: =G6/4 -> 146.19471 | I6: =$H6*Assumptions!$B$47 -> 73.097355 | J6: =$H6*Assumptions!$B$48 -> 109.64603 | K6: =$H6*Assumptions!$B$49 -> 146.19471 | L6: =$H6*Assumptions!$B$50 -> 146.19471 | M6: =SUM(I6:L6) -> 475.1328
A7: =PumpPoints!A7 -> Karachi | B7: =PumpPoints!B7 -> Karachi Central | C7: =PumpPoints!D7 -> C | D7: =PumpPoints!E7 -> KHI-3 | E7: =(PumpPoints!K7+PumpPoints!L7)/Assumptions!$B$8 -> 49062.683 | F7: =IF(C7="S",Assumptions!$B$24,IF(C7="A",Assumptions!$B$25,IF(C7="B",Assumptions!$B$26,Assumptions!$B$27))) -> 0.003 | G7: =E7*F7 -> 147.18805 | H7: =G7/4 -> 36.797012 | I7: =$H7*Assumptions!$B$47 -> 18.398506 | J7: =$H7*Assumptions!$B$48 -> 27.597759 | K7: =$H7*Assumptions!$B$49 -> 36.797012 | L7: =$H7*Assumptions!$B$50 -> 36.797012 | M7: =SUM(I7:L7) -> 119.59029
